<?xml version="1.0" encoding="utf-8"?>
<robot name="JueyingMiniV2">
  <material name="white">
    <color rgba="1 1 1 1" />
  </material>
  <material name="Plastic">
    <color rgba="0.5 0.5 0.99 1" />
  </material>
  <material name="Rubber">
    <color rgba="0.58824 0.66275 0.89412 1" />
  </material>
  <material name="Steel">
    <color rgba="0.69804 0.69804 0.69804 1" />
  </material>
  <material name="Compound">
    <color rgba="0.69804 0.69804 0.69804 1" />
  </material>



  <link name="BASE">
    <visual>
      <geometry>
        <mesh filename="/meshes/BASE.obj" />
      </geometry>
      <material name="Plastic"/>
    </visual>
    <collision>
      <geometry>
        <mesh filename="/meshes/BASE_C.obj" />
      </geometry>
    </collision>
  </link> 

  <joint name="Base2Iner" type="fixed">
    <origin xyz="0 0 0"/>
    <parent link="BASE" />
    <child link="BASE2INER" />
  </joint>

  <link name="BASE_INER">
    <inertial>
      <origin xyz="8.7672E-05 -0.0023116 -0.029338"/>
      <mass value="13.733" />
      <inertia ixx="0.020265" ixy="9.2196E-07" ixz="-9.9163E-05" iyy="0.053164" iyz="1.4796E-06" izz="0.067439" />
    </inertial>
  </link>
  
  <link name="FL_HIP">
    <inertial>
      <origin xyz="-0.0035219 0.00046544 0.00086007"/>
      <mass value="0.7425" />
      <inertia ixx="0.0003652" ixy="-1.1858E-05" ixz="1.3444E-05" iyy="0.00079651" iyz="3.3108E-06" izz="0.00053551" />
    </inertial>
    <visual>
      <geometry>
        <mesh filename="/meshes/FL_HIP.STL" />
      </geometry>
      <material name="Rubber"/>
    </visual>
  </link>

  <joint name="FL_HipX" type="revolute">
    <origin xyz="0.231 0.062 0"/>
    <parent link="BASE" />
    <child link="FL_HIP" />
    <axis xyz="1 0 0" />
    <limit lower="-0.39" upper="0.39" effort="26" velocity="20" />
    <dynamics damping="0.0" friction="0.0" />
  </joint>

  <link name="FL_THIGH">
    <inertial>
      <origin xyz="-0.0032647 -0.0044988 -0.028209"/>
      <mass value="1.4189" />
      <inertia ixx="0.0023668" ixy="4.3765E-06" ixz="0.00010546" iyy="0.0031754" iyz="4.723E-05" izz="0.0012036" />
    </inertial>
    <visual>
      <geometry>
        <mesh filename="/meshes/L_THIGH.obj" />
      </geometry>
      <material name="Compound"/>
    </visual>
    <collision>
      <geometry>
        <mesh filename="/meshes/THIGH_C.obj" />
      </geometry>
    </collision>
  </link>

  <joint name="FL_HipY" type="revolute">
    <origin xyz="0 0.0845 0"/>
    <parent link="FL_HIP" />
    <child link="FL_THIGH" />
    <axis xyz="0 -1 0" />
    <limit lower="-2.76" upper="0.49" effort="26" velocity="20" />
    <dynamics damping="0.0" friction="0.0" />
  </joint>

  <link name="FL_SHANK">
    <inertial>
      <origin xyz="-0.0032793 -3.0273E-06 -0.15776"/>
      <mass value="0.18" />
      <inertia ixx="0.0012178" ixy="5.2585E-08" ixz="5.5726E-05" iyy="0.001232" iyz="4.8941E-08" izz="3.0829E-05" />
    </inertial>
    <visual>
      <geometry>
        <mesh filename="/meshes/SHANK.obj" />
      </geometry>
      <material name="Compound"/>
    </visual>
  </link>

  <joint name="FL_Knee" type="revolute">
    <origin xyz="0 0 -0.25"/>
    <parent link="FL_THIGH" />
    <child link="FL_SHANK" />
    <axis xyz="0 -1 0" />
    <limit lower="0.66" upper="2.84" effort="47" velocity="20" />
    <dynamics damping="0.0" friction="0.0" />
  </joint>

  <link name="FL_FOOT">
    <inertial>
      <mass value="1E-12" />
      <inertia ixx="1E-12" ixy="0" ixz="0" iyy="1E-12" iyz="0" izz="1E-12" />
    </inertial>
    <collision>
      <geometry>
        <sphere radius="0.02"/>
      </geometry>
    </collision>
  </link>

  <joint name="FL_Ankle" type="fixed">
    <origin xyz="0 0.002 -0.25"/>
    <parent link="FL_SHANK" />
    <child link="FL_FOOT" />
  </joint>

  <link name="HL_HIP">
    <inertial>
      <origin xyz="-0.45848 0.0014957 0.00086009"/>
      <mass value="0.7425" />
      <inertia ixx="0.00036521" ixy="1.1859E-05" ixz="-1.3444E-05" iyy="0.00079652" iyz="3.311E-06" izz="0.00053551" />
    </inertial>
    <visual>
      <geometry>
        <mesh filename="/meshes/HL_HIP.STL" />
      </geometry>
      <material name="Rubber"/>
    </visual>
  </link>

  <joint name="HL_HipX" type="revolute">
    <origin xyz="0.231 0.062 0"/>
    <parent link="BASE" />
    <child link="HL_HIP" />
    <axis xyz="-1 0 0" />
    <limit lower="-0.39" upper="0.39" effort="26" velocity="20" />
    <dynamics damping="0.0" friction="0.0" />
  </joint>

  <link name="HL_THIGH">
    <inertial>
      <origin xyz="-0.0032647 -0.0050062 -0.028209"/>
      <mass value="1.4189" />
      <inertia ixx="0.0023668" ixy="4.3765E-06" ixz="0.00010546" iyy="0.0031754" iyz="4.723E-05" izz="0.0012036" />
    </inertial>
    <visual>
      <geometry>
        <mesh filename="/meshes/L_THIGH.obj" />
      </geometry>
      <material name="Compound"/>
    </visual>
    <collision>
      <geometry>
        <mesh filename="/meshes/THIGH_C.obj" />
      </geometry>
    </collision>
  </link>

  <joint name="HL_HipY" type="revolute">
    <origin xyz="-0.462 0.0845 0"/>
    <parent link="HL_HIP" />
    <child link="HL_THIGH" />
    <axis xyz="0 -1 0" />
    <limit lower="-2.76" upper="0.49" effort="26" velocity="20" />
  </joint>

  <link name="HL_SHANK">
    <inertial>
      <origin xyz="-0.0032793 -3.0254E-06 -0.15776"/>
      <mass value="0.18" />
      <inertia ixx="0.0012178" ixy="5.2582E-08" ixz="5.5726E-05" iyy="0.001232" iyz="4.897E-08" izz="3.0829E-05" />
    </inertial>
    <visual>
      <geometry>
        <mesh filename="/meshes/SHANK.obj" />
      </geometry>
      <material name="Compound"/>
    </visual>
  </link>

  <joint name="HL_Knee" type="revolute">
    <origin xyz="0 0 -0.25"/>
    <parent link="HL_THIGH" />
    <child link="HL_SHANK" />
    <axis xyz="0 -1 0" />
    <limit lower="0.66" upper="2.84" effort="47" velocity="20" />
    <dynamics damping="0.0" friction="0.0" />
  </joint>

  <link name="HL_FOOT">
    <inertial>
      <mass value="1E-12" />
      <inertia ixx="1E-12" ixy="0" ixz="0" iyy="1E-12" iyz="0" izz="1E-12" />
    </inertial>
    <collision>
      <geometry>
        <sphere radius="0.02"/>
      </geometry>
    </collision>
  </link>

  <joint name="HL_Ankle" type="fixed">
    <origin xyz="0 0.002 -0.25"/>
    <parent link="HL_SHANK" />
    <child link="HL_FOOT" />
  </joint>

  <link name="FR_HIP">
    <inertial>
      <origin xyz="-0.0035219 -0.00034419 0.00086009"/>
      <mass value="0.7425" />
      <inertia ixx="0.00036521" ixy="1.1859E-05" ixz="1.3444E-05" iyy="0.00079652" iyz="-3.311E-06" izz="0.00053551" />
    </inertial>
    <visual>
      <geometry>
        <mesh filename="/meshes/FR_HIP.STL" />
      </geometry>
      <material name="Rubber"/>
    </visual>
  </link>

  <joint name="FR_HipX" type="revolute">
    <origin xyz="0.231 -0.062 0"/>
    <parent link="BASE" />
    <child link="FR_HIP" />
    <axis xyz="-1 0 0" />
    <limit lower="-0.39" upper="0.39" effort="26" velocity="20" />
    <dynamics damping="0.0" friction="0.0" />
  </joint>

  <link name="FR_THIGH">
    <inertial>
      <origin xyz="-0.003213 0.0046192 -0.02844"/>
      <mass value="1.4215" />
      <inertia ixx="0.0023856" ixy="-4.1648E-06" ixz="0.00010795" iyy="0.0031915" iyz="-4.9512E-05" izz="0.0011996" />
    </inertial>
    <visual>
      <geometry>
        <mesh filename="/meshes/R_THIGH.obj" />
      </geometry>
      <material name="Compound"/>
    </visual>
    <collision>
      <geometry>
        <mesh filename="/meshes/THIGH_C.obj" />
      </geometry>
    </collision>
  </link>

  <joint name="FR_HipY" type="revolute">
    <origin xyz="0 -0.0845 0"/>
    <parent link="FR_HIP" />
    <child link="FR_THIGH" />
    <axis xyz="0 -1 0" />
    <limit lower="-2.76" upper="0.49" effort="26" velocity="20" />
  </joint>

  <link name="FR_SHANK">
    <inertial>
      <origin xyz="-0.0032793 -3.027E-06 -0.15776"/>
      <mass value="0.18" />
      <inertia ixx="0.0012178" ixy="5.2585E-08" ixz="5.5726E-05" iyy="0.001232" iyz="4.8945E-08" izz="3.0829E-05" />
    </inertial>
    <visual>
      <geometry>
        <mesh filename="/meshes/SHANK.obj" />
      </geometry>
      <material name="Compound"/>
    </visual>
  </link>

  <joint name="FR_Knee" type="revolute">
    <origin xyz="0 0 -0.25"/>
    <parent link="FR_THIGH" />
    <child link="FR_SHANK" />
    <axis xyz="0 -1 0" />
    <limit lower="0.66" upper="2.84" effort="47" velocity="20" />
    <dynamics damping="0.0" friction="0.0" />
  </joint>

  <link name="FR_FOOT">
    <inertial>
      <mass value="1E-12" />
      <inertia ixx="1E-12" ixy="0" ixz="0" iyy="1E-12" iyz="0" izz="1E-12" />
    </inertial>
    <collision>
      <geometry>
        <sphere radius="0.02"/>
      </geometry>
    </collision>
  </link>

  <joint name="FR_Ankle" type="fixed">
    <origin xyz="0 -0.002 -0.25"/>
    <parent link="FR_SHANK" />
    <child link="FR_FOOT" />
  </joint>

  <link name="HR_HIP">
    <inertial>
      <origin xyz="0.0035219 -0.00046544 0.00086007"/>
      <mass value="0.7425" />
      <inertia ixx="0.0003652" ixy="-1.1858E-05" ixz="-1.3444E-05" iyy="0.00079651" iyz="-3.3108E-06" izz="0.00053551" />
    </inertial>
    <visual>
      <geometry>
        <mesh filename="/meshes/HR_HIP.STL" />
      </geometry>
      <material name="Rubber"/>
    </visual>
  </link>

  <joint name="HR_HipX" type="revolute">
    <origin xyz="-0.231 -0.062 0"/>
    <parent link="BASE" />
    <child link="HR_HIP" />
    <axis xyz="1 0 0" />
    <limit lower="-0.39" upper="0.39" effort="26" velocity="20" />
    <dynamics damping="0.0" friction="0.0" />
  </joint>

  <link name="HR_THIGH">
    <inertial>
      <origin xyz="-0.003213 0.0042647 -0.02844"/>
      <mass value="1.4215" />
      <inertia ixx="0.0023856" ixy="-4.1648E-06" ixz="0.00010795" iyy="0.0031915" iyz="-4.9512E-05" izz="0.0011996" />
    </inertial>
    <visual>
      <geometry>
        <mesh filename="/meshes/R_THIGH.obj" />
      </geometry>
      <material name="Compound"/>
    </visual>
    <collision>
      <geometry>
        <mesh filename="/meshes/THIGH_C.obj" />
      </geometry>
    </collision>
  </link>

  <joint name="HR_HipY" type="revolute">
    <origin xyz="0 -0.0845 0"/>
    <parent link="HR_HIP" />
    <child link="HR_THIGH" />
    <axis xyz="0 -1 0" />
    <limit lower="-2.76" upper="0.49" effort="26" velocity="20" />
    <dynamics damping="0.0" friction="0.0" />
  </joint>

  <link name="HR_SHANK">
    <inertial>
      <origin xyz="-0.0032793 -3.0254E-06 -0.15776"/>
      <mass value="0.18" />
      <inertia ixx="0.0012178" ixy="5.2582E-08" ixz="5.5726E-05" iyy="0.001232" iyz="4.897E-08" izz="3.0829E-05" />
    </inertial>
    <visual>
      <geometry>
        <mesh filename="/meshes/SHANK.obj" />
      </geometry>
      <material name="Compound"/>
    </visual>
  </link>

  <joint name="HR_Knee" type="revolute">
    <origin xyz="0 0 -0.25"/>
    <parent link="HR_THIGH" />
    <child link="HR_SHANK" />
    <axis xyz="0 -1 0" />
    <limit lower="0.66" upper="2.84" effort="47" velocity="20" />
    <dynamics damping="0.0" friction="0.0" />
  </joint>

  <link name="HR_FOOT">
    <inertial>
      <mass value="1E-12" />
      <inertia ixx="1E-12" ixy="0" ixz="0" iyy="1E-12" iyz="0" izz="1E-12" />
    </inertial>
    <collision>
      <geometry>
        <sphere radius="0.02"/>
      </geometry>
    </collision>
  </link>

  <joint name="HR_Ankle" type="fixed">
    <origin xyz="0 -0.002 -0.25"/>
    <parent link="HR_SHANK" />
    <child link="HR_FOOT" />
  </joint>

  <link name="LIDAR">
    <inertial>
      <mass value="1E-12" />
      <inertia ixx="1E-12" ixy="0" ixz="0" iyy="1E-12" iyz="0" izz="1E-12" />
    </inertial>
    <visual>
      <geometry>
        <mesh filename="/meshes/LIDAR.obj" />
      </geometry>
      <material name="white"/>
    </visual>
  </link>

  <joint name="Base2LiDAR" type="fixed">
    <origin xyz="0.1895 -0.0545 0.058"/>
    <parent link="BASE" />
    <child link="LIDAR" />
  </joint>

</robot>